Workbook

Sheet 00-Anleitung
A1: Modulares Rack-Modell — Mikrogruen-System
A3: Prinzip | B3: Ein offenes Staenderwerk traegt N gleiche Klimamodule.
B4: Jedes Modul ist ein geschlossener, gedaemmter Einschub mit eigenem Klima.
B5: Aendere nur 01-Eingaben; Geometrie, Klima, Elektrik und Kosten rechnen nach.
A7: Legende
A8: Blau auf gelb | B8: Eingabe — hier darfst du schreiben
A9: Schwarz | B9: Formel — nicht ueberschreiben
A10: Gruen hinterlegt | B10: Kernergebnis / Uebergabewert an die Konstruktion
A11: Spalte D | B11: Quelle bzw. Annahme, auf der ein Wert beruht
A13: Blattstruktur
A14: 01-Eingaben | B14: Alle veraenderlichen Ausgangsgroessen
A15: 02-GN-Normmasse | B15: DIN 66075 Nachschlagetabelle
A16: 03-Modul | B16: Ein einzelner Einschub: Raster, Innen-/Aussenmasse, Blech, Daemmung
A17: 04-Rack | B17: Staenderwerk, Etagenteilung, Stellflaeche, Flaechenproduktivitaet
A18: 05-Licht | B18: PPFD und DLI je Modul, LED-Leistung gesamt
A19: 06-Klima | B19: U-Wert, LED-Abwaerme, Lueftungsbedarf, Etagenkopplung
A20: 07-Wasser | B20: Bedarf je Modul und gesamt, Ventile, Reservoir
A21: 08-Elektrik | B21: Leistungsbilanz, Netzteile, I2C-Adressbedarf
A22: 09-Ertrag | B22: Saat, Ernte, Jahresleistung
A23: 10-Kosten | B23: Modulkosten x Etagenzahl plus Rack und Zentraltechnik
A25: Modulschnittstelle — was fix bleibt, wenn alles andere sich aendert
A26: Mechanisch | B26: Aussenmasse des Moduls und Lochrasterteilung des Staenderwerks
A27: Elektrisch | B27: Ein Steckverbinder je Modul: Versorgung, GND, Bus
A28: Hydraulisch | B28: Eine Schnellkupplung Vorlauf, ein Ablauf in die Sammelrinne
B29: Solange diese drei gleich bleiben, ist jedes Modul gegen jedes andere tauschbar.
A31: Beispielzeile
A32: Feld | B32: Wert | D32: Einheit
A33: GN-Format | B33: 1/9 | D33: Text, exakt wie in 02-GN-Normmasse
A34: Trays je Etage | B34: 6 | D34: Stueck
A35: Anzahl Etagen | B35: 3 | D35: Stueck

Sheet 02-GN-Normmasse
A1: Gastronorm-Grundmasse nach DIN 66075 / EN 631
A3: Format | B3: Laenge mm | C3: Breite mm | D3: Flaeche cm² | E3: Anmerkung
A4: 2/1 | B4: 650 | C4: 530 | D4: =B4*C4/100 -> 3445 | E4: Doppelmodul
A5: 1/1 | B5: 530 | C5: 325 | D5: =B5*C5/100 -> 1722.5 | E5: Grundmodul
A6: 1/2 | B6: 325 | C6: 265 | D6: =B6*C6/100 -> 861.25
A7: 2/3 | B7: 354 | C7: 325 | D7: =B7*C7/100 -> 1150.5
A8: 1/3 | B8: 325 | C8: 176 | D8: =B8*C8/100 -> 572
A9: 1/4 | B9: 265 | C9: 162 | D9: =B9*C9/100 -> 429.3
A10: 1/6 | B10: 176 | C10: 162 | D10: =B10*C10/100 -> 285.12
A11: 1/9 | B11: 176 | C11: 108 | D11: =B11*C11/100 -> 190.08 | E11: kleinste Norm-Fraktion
A13: Quelle | B13: DIN 66075 / EN 631, Aussenmasse der Behaelteroeffnung
A14: Hinweis | B14: Formate sind flaechenkompatibel: zwei GN 1/9 belegen die Flaeche eines GN 1/6

Sheet 01-Eingaben
A1: Eingangsvariablen — nur hier aendern
A3: A Trays und Raster (je Etage)
A4: Groesse | B4: Wert | C4: Einheit | D4: Quelle / Annahme
A5: GN-Format | B5: 1/9 | C5: Text | D5: Muss exakt einem Eintrag in 02-GN-Normmasse entsprechen
A6: Trayhoehe (Behaeltertiefe) | B6: 40 | C6: mm | D6: Genormte Stufe: 20/40/65/100/150
A7: Trays je Etage | B7: 6 | C7: Stk | D7: Frei waehlbar
A8: Spalten im Raster | B8: 2 | C8: Stk | D8: Reihen werden daraus berechnet
A9: Ausrichtung (1 = Laenge waagerecht, 2 = hochkant) | B9: 1 | C9: - | D9: Beeinflusst Rasterform bei gleicher Flaeche
A10: Fuegespalt zwischen Trays | B10: 2 | C10: mm | D10: Nur Fertigungs- und Auszugstoleranz; Griff sitzt unter dem Boerdelrand
A11: Abstand Raster zur Modulwand | B11: 25 | C11: mm | D11: Umluft und Reinigungszugang
A12: Hoehe Auflageschiene | B12: 15 | C12: mm | D12: Traegt den Boerdelrand, schafft Griffraum darunter
A13: B Modulhoehen
A14: Groesse | B14: Wert | C14: Einheit | D14: Quelle / Annahme
A15: Max. Pflanzenhoehe ueber Trayrand | B15: 100 | C15: mm | D15: Groesste geplante Sorte bestimmt den Wert
A16: Abstand LED zur Pflanzenspitze | B16: 150 | C16: mm | D16: Kompromiss Ausleuchtung / Waermeeintrag
A17: Bauhoehe LED inkl. Profil | B17: 15 | C17: mm | D17: Streifen auf Alu-Profil
A18: Hoehenreserve | B18: 20 | C18: mm | D18: Toleranz Fertigung und Montage
A19: Substrathoehe im Tray | B19: 25 | C19: mm | D19: Ueblich 20-30 mm fuer Mikrogruen
A20: C Rack und Etagen
A21: Groesse | B21: Wert | C21: Einheit | D21: Quelle / Annahme
A22: Etagen im Staenderwerk (Z) | B22: 4 | C22: Stk | D22: Zusammen mit X und Y (Abschnitt Q) das Raster X x Y x Z — nachtraeglich nicht erweiterbar
A23: Davon bereits gedaemmt ausgefuehrt | B23: 0 | C23: Stk | D23: 0 = alle einschalig; Liner jederzeit nachruestbar
A24: Lochrasterteilung im Staender | B24: 25 | C24: mm | D24: Analog 19-Zoll-Technik: Module rasten in Vielfachen ein
A25: Spiel Modul zu Staender je Seite | B25: 3 | C25: mm | D25: Einschub muss ohne Klemmen laufen
A26: Kantenlaenge Rahmenprofil | B26: 30 | C26: mm | D26: Vierkantrohr Staenderwerk, 30x30x2 als Ausgangswert
A27: Sockelhoehe | B27: 60 | C27: mm | D27: Bodenfreiheit, Stellfuesse, Reinigung darunter
A28: D Technikschraenke (extern, ausserhalb des Racks)
A29: Groesse | B29: Wert | C29: Einheit | D29: Quelle / Annahme
A30: Breite Elektronikschrank | B30: 300 | C30: mm | D30: Gaengiges Wandgehaeuse-Mass; Hutschiene mit Netzteilen, ESP32, Relais
A31: Hoehe Elektronikschrank | B31: 300 | C31: mm | D31: Reicht fuer eine Hutschienenebene plus Klemmraum
A32: Breite Hydraulikschrank | B32: 300 | C32: mm | D32: Reservoir und Zentralpumpe
A33: Hoehe Hydraulikschrank | B33: 300 | C33: mm | D33: Aus dem Reservoirbedarf abgeleitet, siehe Pruefung in 07-Wasser
A34: E Werkstoffe und Daemmung
A35: Groesse | B35: Wert | C35: Einheit | D35: Quelle / Annahme
A36: Blechstaerke Modulschale | B36: 1 | C36: mm | D36: V2A 1.4301, Modul traegt keine Last — Rack traegt
A37: Auslegungs-Daemmstaerke | B37: 20 | C37: mm | D37: Legt das Aussenmass fest und bleibt fix — auch bei einschaligem Bau
A38: Waermeleitfaehigkeit Daemmstoff | B38: 0.04 | C38: W/(m·K) | D38: Schaumglas ~0,040; mineralisch, kein Ausgasen, kein Mikroplastik
A39: Waermeuebergang innen | B39: 8 | C39: W/(m²·K) | D39: Freie Konvektion mit leichter Umluft
A40: Waermeuebergang aussen | B40: 8 | C40: W/(m²·K) | D40: Ruhende Raumluft
A41: Verschnittzuschlag Blech | B41: 0.15 | C41: - | D41: Anteil, Wasserstrahl mit Haltestegen
...

Sheet 03-Modul
A1: Ein Modul — Raster, Masse, Ausbaustufen
A3: Auslegungsprinzip | B3: Die Aussenkontur folgt immer dem gedaemmten Endzustand.
B4: Phase 1 baut nur die Aussenschale, Phase 2 setzt Daemmung und Liner nach innen ein.
B5: Dadurch bleiben Rack, Etagenteilung und Schnittstelle in beiden Stufen identisch.
A7: Traymasse aus der Norm
A8: Groesse | B8: Wert | C8: Einheit | D8: Herleitung
A9: Traylaenge | B9: =INDEX('02-GN-Normmasse'!$B$4:$B$11,MATCH('01-Eingaben'!$B$5,'02-GN-Normmasse'!$A$4:$A$11,0)) -> 176 | C9: mm | D9: Nachschlag in 02-GN-Normmasse
A10: Traybreite | B10: =INDEX('02-GN-Normmasse'!$C$4:$C$11,MATCH('01-Eingaben'!$B$5,'02-GN-Normmasse'!$A$4:$A$11,0)) -> 108 | C10: mm | D10: Nachschlag in 02-GN-Normmasse
A11: Trayausdehnung X | B11: =IF('01-Eingaben'!$B$9=1,'03-Modul'!$B$9,'03-Modul'!$B$10) -> 176 | C11: mm | D11: abhaengig von der Ausrichtung
A12: Trayausdehnung Y | B12: =IF('01-Eingaben'!$B$9=1,'03-Modul'!$B$10,'03-Modul'!$B$9) -> 108 | C12: mm | D12: abhaengig von der Ausrichtung
A13: Flaeche je Tray | B13: ='03-Modul'!$B$9*'03-Modul'!$B$10/100 -> 190.08 | C13: cm² | D13: Laenge x Breite
A14: Raster
A15: Groesse | B15: Wert | C15: Einheit | D15: Herleitung
A16: Reihen | B16: =ROUNDUP('01-Eingaben'!$B$7/'01-Eingaben'!$B$8,0) -> 3 | C16: Stk | D16: aufgerundet aus Trays je Etage / Spalten
A17: Rasterfelder | B17: ='01-Eingaben'!$B$8*'03-Modul'!$B$16 -> 6 | C17: Stk | D17: Spalten x Reihen
A18: Freie Felder | B18: ='03-Modul'!$B$17-'01-Eingaben'!$B$7 -> 0 | C18: Stk | D18: Reserve fuer Ausfallsorte
A19: Rasterbreite X | B19: ='01-Eingaben'!$B$8*'03-Modul'!$B$11+('01-Eingaben'!$B$8-1)*'01-Eingaben'!$B$10 -> 354 | C19: mm | D19: Trays plus Fuegespalt
A20: Rastertiefe Y | B20: ='03-Modul'!$B$16*'03-Modul'!$B$12+('03-Modul'!$B$16-1)*'01-Eingaben'!$B$10 -> 328 | C20: mm | D20: Trays plus Fuegespalt
A21: Anbauflaeche netto je Modul | B21: ='01-Eingaben'!$B$7*'03-Modul'!$B$13/10000 -> 0.114048 | C21: m² | D21: Basis fuer Wasser, Substrat, Ertrag
A22: Rasterflaeche brutto je Modul | B22: ='03-Modul'!$B$19*'03-Modul'!$B$20/1000000 -> 0.116112 | C22: m² | D22: Basis fuer die Lichtrechnung
A23: Packungsgrad | B23: ='03-Modul'!$B$21/'03-Modul'!$B$22 -> 0.98222406 | C23: - | D23: Anteil Nutzflaeche an Rasterflaeche
A24: Sollinnenraum (gedaemmter Endzustand)
A25: Groesse | B25: Wert | C25: Einheit | D25: Herleitung
A26: Soll-Innenbreite | B26: ='03-Modul'!$B$19+2*'01-Eingaben'!$B$11 -> 404 | C26: mm | D26: Raster plus Wandabstand
A27: Soll-Innentiefe | B27: ='03-Modul'!$B$20+2*'01-Eingaben'!$B$11 -> 378 | C27: mm | D27: Raster plus Wandabstand
A28: Soll-Innenhoehe | B28: ='01-Eingaben'!$B$12+'01-Eingaben'!$B$6+'01-Eingaben'!$B$15+'01-Eingaben'!$B$16+'01-Eingaben'!$B$17+'01-Eingaben'!$B$18 -> 340 | C28: mm | D28: Schiene + Tray + Pflanze + Lichtabstand + LED + Reserve
A29: Wandaufbau im Endzustand | B29: =2*'01-Eingaben'!$B$36+'01-Eingaben'!$B$37 -> 22 | C29: mm | D29: Aussenschale + Daemmung + Liner
A30: Aussenkontur — in beiden Ausbaustufen gleich
A31: Groesse | B31: Wert | C31: Einheit | D31: Herleitung
A32: Aussenbreite Modul | B32: ='03-Modul'!$B$26+2*'03-Modul'!$B$29 -> 448 | C32: mm | D32: Sollinnenmass plus Endwandaufbau
A33: Aussentiefe Modul | B33: ='03-Modul'!$B$27+2*'03-Modul'!$B$29 -> 422 | C33: mm | D33: Sollinnenmass plus Endwandaufbau
A34: Aussenhoehe Modul | B34: ='03-Modul'!$B$28+2*'03-Modul'!$B$29 -> 384 | C34: mm | D34: Sollinnenmass plus Endwandaufbau
A35: Huellflaeche aussen | B35: =2*('03-Modul'!$B$32*'03-Modul'!$B$33+'03-Modul'!$B$32*'03-Modul'!$B$34+'03-Modul'!$B$33*'03-Modul'!$B$34)/1000000 -> 1.046272 | C35: m² | D35: Basis fuer Waermedurchgang und Blechbedarf
A36: Bodenflaeche Modul | B36: ='03-Modul'!$B$32*'03-Modul'!$B$33/1000000 -> 0.189056 | C36: m² | D36: Kopplungsflaeche zur Nachbaretage
A37: Huellflaeche Liner (vollstaendig) | B37: =2*('03-Modul'!$B$26*'03-Modul'!$B$27+'03-Modul'!$B$26*'03-Modul'!$B$28+'03-Modul'!$B$27*'03-Modul'!$B$28)/1000000 -> 0.837184 | C37: m² | D37: Innenschale bei Volldaemmung
A38: Flaeche Boden und Decke | B38: ='03-Modul'!$B$36*2 -> 0.378112 | C38: m² | D38: die beiden Flaechen zu den Nachbaretagen
A39: Flaeche der Seitenwaende | B39: ='03-Modul'!$B$35-'03-Modul'!$B$38 -> 0.66816 | C39: m² | D39: die vier Flaechen zur Umgebung
A40: Liner nur Boden und Decke | B40: =2*'03-Modul'!$B$26*'03-Modul'!$B$27/1000000 -> 0.305424 | C40: m² | D40: Innenschale bei Teildaemmung
A41: Ausbaustufe 1 — einschalig
A42: Groesse | B42: Wert | C42: Einheit | D42: Herleitung
...

Sheet 04-Rack
A1: Staenderwerk und Etagenteilung
A3: Teilung
A4: Groesse | B4: Wert | C4: Einheit | D4: Herleitung
A5: Etagenteilung (Lochraster) | B5: =ROUNDUP(('03-Modul'!$B$34+2*'01-Eingaben'!$B$25)/'01-Eingaben'!$B$24,0)*'01-Eingaben'!$B$24 -> 400 | C5: mm | D5: Modulhoehe plus Spiel, auf Rastermass aufgerundet
A6: Ungenutzte Hoehe je Etage | B6: ='04-Rack'!$B$5-'03-Modul'!$B$34-2*'01-Eingaben'!$B$25 -> 10 | C6: mm | D6: Rundungsverlust — klein halten durch Wahl des Rastermasses
A7: Hoehe Anschlussfeld im Rack | B7: ='01-Eingaben'!$B$94 -> 0 | C7: mm | D7: 0, solange Elektronik und Hydraulik in externen Schraenken sitzen
A8: Breitenbedarf Technik im Rack | B8: 0 | C8: mm | D8: 0 — Technik ist extern; Wert bleibt als Platzhalter fuer ein spaeteres Verteilerfach
A9: Rackmasse
A10: Groesse | B10: Wert | C10: Einheit | D10: Herleitung
A11: Lichte Breite im Staender | B11: =MAX('01-Eingaben'!$B$133*('03-Modul'!$B$32+2*'01-Eingaben'!$B$25)+('01-Eingaben'!$B$133-1)*'01-Eingaben'!$B$26,'04-Rack'!$B$8) -> 454 | C11: mm | D11: X Modulspalten plus Spiel, Staender zwischen den Spalten geteilt
A12: Aussenbreite Rack | B12: ='04-Rack'!$B$11+2*'01-Eingaben'!$B$26 -> 514 | C12: mm | D12: lichte Breite plus Staenderprofile
A13: Aussentiefe Rack | B13: =2*'01-Eingaben'!$B$26+'01-Eingaben'!$B$134*('01-Eingaben'!$B$25+'03-Modul'!$B$33+'01-Eingaben'!$B$92)+ROUNDUP('01-Eingaben'!$B$134/2,0)*'01-Eingaben'!$B$93 -> 550 | C13: mm | D13: Profile + Y Reihen (Spiel + Modul + Schnittstelle) + ein Versorgungsstrang je Reihenpaar
A14: Aussenhoehe Rack | B14: ='01-Eingaben'!$B$22*'04-Rack'!$B$5+'04-Rack'!$B$7+'01-Eingaben'!$B$27+2*'01-Eingaben'!$B$26 -> 1720 | C14: mm | D14: Etagen + Technikfach + Sockel + Rahmen
A15: Stellflaeche | B15: ='04-Rack'!$B$12*'04-Rack'!$B$13/1000000 -> 0.2827 | C15: m² | D15: Grundflaeche im Raum
A16: Leistung des Racks
A17: Groesse | B17: Wert | C17: Einheit | D17: Herleitung
A18: Anbauflaeche netto gesamt | B18: ='03-Modul'!$B$21*'01-Eingaben'!$B$96 -> 0.114048 | C18: m² | D18: je Modul x Etagenzahl
A19: Rasterflaeche gesamt | B19: ='03-Modul'!$B$22*'01-Eingaben'!$B$96 -> 0.116112 | C19: m² | D19: je Modul x Etagenzahl
A20: Trays gesamt | B20: ='01-Eingaben'!$B$7*'01-Eingaben'!$B$96 -> 6 | C20: Stk | D20: entspricht der maximalen Sortenzahl gleichzeitig
A21: Flaechenfaktor | B21: ='04-Rack'!$B$18/'04-Rack'!$B$15 -> 0.40342412 | C21: m²/m² | D21: Anbauflaeche je Quadratmeter Stellflaeche — der Sinn des Racks
A22: Materialbedarf Rack
A23: Groesse | B23: Wert | C23: Einheit | D23: Herleitung
A24: Profillaenge Staenderwerk | B24: =(('01-Eingaben'!$B$133+1)*('01-Eingaben'!$B$134+1)*('04-Rack'!$B$14-25)+IF('01-Eingaben'!$B$151=1,'01-Eingaben'!$B$22+2,2)*(('01-Eingaben'!$B$134+1)*('04-Rack'!$B$11-('01-Eingaben'!$B$133-1)*'01-Eingaben'!$B$26)+('01-Eingaben'!$B$133+1)*('04-Rack'!$B$13-('01-Eingaben'!$B$134+1)*'01-Eingaben'!$B$26)))/1000 -> 10.556 | C24: m | D24: Staender ueber den Fuessen plus Traversenringe; Bauart 2 behaelt nur Boden- und Kopfring (01-Eingaben Zeile 151)
A25: Blech Rueckwand / Kanalabdeckung | B25: =IF('01-Eingaben'!$B$163=1,'04-Rack'!$B$11,IF('01-Eingaben'!$B$163=2,'01-Eingaben'!$B$164,0))*'04-Rack'!$B$14/1000000*(1+'01-Eingaben'!$B$41)*ROUNDUP('01-Eingaben'!$B$134/2,0) -> 0 | C25: m² | D25: vollflaechig, nur Kanalstreifen oder ganz offen — bei zweireihigem Rack je Reihenpaar eine Ebene
A26: Blech gesamt | B26: ='03-Modul'!$B$52*'01-Eingaben'!$B$23+'03-Modul'!$B$51*('01-Eingaben'!$B$96-'01-Eingaben'!$B$23)+'04-Rack'!$B$25 -> 1.7028054 | C26: m² | D26: gedaemmte und einschalige Module plus Rackverkleidung
A27: Bestueckung pruefen | B27: =IF(AND('01-Eingaben'!$B$96<='04-Rack'!$B$37,'01-Eingaben'!$B$23<='01-Eingaben'!$B$96),"ok","FEHLER: mehr Module als Modulplaetze oder mehr gedaemmte als bestueckte") -> ok
A28: Freie Modulplaetze | B28: ='04-Rack'!$B$37-'01-Eingaben'!$B$96 -> 3 | C28: Stk | D28: spaeter nachruestbar, ohne das Rack zu aendern
A29: Pruefung | B29: Ergebnis | D29: Bedeutung
A30: Passen alle Trays ins Raster? | B30: =IF('01-Eingaben'!$B$7<='03-Modul'!$B$17,"ok","FEHLER: Spaltenzahl erhoehen") -> ok
A31: Was bestimmt die Rackbreite? | B31: =IF('04-Rack'!$B$8>'03-Modul'!$B$32+2*'01-Eingaben'!$B$25,"Technikfach — Modul koennte breiter werden","Modul") -> Modul | D31: Hinweis auf ungenutztes Breitenpotenzial
A32: Rastermass sinnvoll gewaehlt? | B32: =IF('04-Rack'!$B$6<='01-Eingaben'!$B$24/2,"ok","viel Rundungsverlust — Rastermass oder Modulhoehe anpassen") -> ok
A33: Rackhoehe erreichbar? | B33: =IF('04-Rack'!$B$14<=2000,"ok — oberste Etage ohne Tritt erreichbar","oberste Etage nur mit Tritt bedienbar") -> ok — oberste Etage ohne Tritt erreichbar | D33: Ergonomie beim taeglichen Kontrollgang
A35: Rasterform X x Y x Z
A36: Groesse | B36: Wert | C36: Einheit | D36: Herleitung
A37: Modulplaetze gesamt | B37: ='01-Eingaben'!$B$133*'01-Eingaben'!$B$134*'01-Eingaben'!$B$22 -> 4 | C37: Stk | D37: X x Y x Z — die Kapazitaet des Staenderwerks
A38: Modulplaetze je Ebene | B38: ='01-Eingaben'!$B$133*'01-Eingaben'!$B$134 -> 1 | C38: Stk | D38: eine Ebene des Rasters
A39: Belegte Ebenen | B39: =ROUNDUP('01-Eingaben'!$B$96/'04-Rack'!$B$38,0) -> 1 | C39: Stk | D39: von unten aufgefuellt — bestimmt den Schwerpunkt
A40: Zugang | B40: =IF('01-Eingaben'!$B$134=1,"einseitig — Rack gehoert an die Wand","beidseitig — Rack steht frei im Raum") -> einseitig — Rack gehoert an die Wand | D40: folgt aus der Reihenzahl Y
A41: Pruefung Rastertiefe | B41: =IF('01-Eingaben'!$B$134<=2,"ok","FEHLER: mehr als zwei Reihen sind ohne Bediengang nicht erreichbar") -> ok | D41: Module werden nach vorn gezogen
A42: Profillaenge je Modulplatz | B42: ='04-Rack'!$B$24/'04-Rack'!$B$37 -> 2.639 | C42: m/Platz | D42: sinkt, je wuerfelfoermiger das Raster wird
...

Sheet 05-Licht
A1: Lichtrechnung je Modul
A3: Bedarf
A4: Groesse | B4: Wert | C4: Einheit | D4: Herleitung
A5: Erforderlicher Photonenstrom je Modul | B5: ='01-Eingaben'!$B$44*'03-Modul'!$B$22 -> 23.2224 | C5: µmol/s | D5: Ziel-PPFD x Rasterflaeche
A6: Erforderliche LED-Leistung je Modul | B6: ='05-Licht'!$B$5/'01-Eingaben'!$B$46 -> 12.901333 | C6: W | D6: Photonenstrom / Effizienz
A7: Elektrisch noetige Streifenlaenge | B7: ='05-Licht'!$B$6/'01-Eingaben'!$B$47 -> 0.92152381 | C7: m | D7: Leistung / Leistung je Meter
A8: Geometrisch noetige Laenge | B8: ='03-Modul'!$B$19/1000*'03-Modul'!$B$16 -> 1.062 | C8: m | D8: je Trayreihe eine Bahn ueber die Rasterbreite
A9: Gewaehlte Laenge je Modul | B9: =ROUNDUP(MAX('05-Licht'!$B$7,'05-Licht'!$B$8)*10,0)/10 -> 1.1 | C9: m | D9: auf volle 10 cm aufgerundet
A10: Ist-Zustand
A11: Groesse | B11: Wert | C11: Einheit | D11: Herleitung
A12: LED-Leistung je Modul | B12: ='05-Licht'!$B$9*'01-Eingaben'!$B$47 -> 15.4 | C12: W | D12: Laenge x W/m
A13: LED-Leistung gesamt | B13: ='05-Licht'!$B$12*'01-Eingaben'!$B$96 -> 15.4 | C13: W | D13: je Modul x Etagenzahl
A14: Erreichte PPFD | B14: ='05-Licht'!$B$12*'01-Eingaben'!$B$46/'03-Modul'!$B$22 -> 238.73501 | C14: µmol/m²/s | D14: installierter Photonenstrom / Rasterflaeche
A15: Tageslichtsumme DLI | B15: ='05-Licht'!$B$14*'01-Eingaben'!$B$45*3600/1000000 -> 13.751137 | C15: mol/m²/Tag | D15: PPFD x Stunden x 3600 / 1e6
A16: Bewertung DLI | B16: =IF('05-Licht'!$B$15<6,"zu niedrig — vergeilte Pflanzen",IF('05-Licht'!$B$15>16,"hoch — Blattbrand und Stromkosten pruefen","im Zielbereich")) -> im Zielbereich | D16: Richtwert Mikrogruen 6-16 mol/m²/Tag
A17: Energie Licht je Tag gesamt | B17: ='05-Licht'!$B$13*'01-Eingaben'!$B$45/1000 -> 0.2464 | C17: kWh | D17: Leistung x Photoperiode

Sheet 06-Klima
A1: Klimazonen — beide Ausbaustufen im Vergleich
A3: Grundgedanke | B3: In einem kleinen Modul ist die LED die dominierende Waermequelle.
B4: Klimazonen entstehen ueber gesteuerte Waermeabfuhr, nicht ueber Heizen.
B5: Daemmung dient der Entkopplung der Etagen, nicht der Temperaturhaltung.
A7: Waermequellen im Modul
A8: Groesse | B8: Wert | C8: Einheit | D8: Herleitung
A9: Abwaerme LED | B9: ='05-Licht'!$B$12*'01-Eingaben'!$B$52 -> 14.63 | C9: W | D9: nahezu die gesamte elektrische Leistung
A10: Interne Waermelast | B10: ='06-Klima'!$B$9+'01-Eingaben'!$B$53 -> 16.13 | C10: W | D10: LED plus Luefter
A11: Stufe 1 — einschalig
A12: Groesse | B12: Wert | C12: Einheit | D12: Herleitung
A13: U-Wert der Wand | B13: =1/(1/'01-Eingaben'!$B$39+1/'01-Eingaben'!$B$40) -> 4 | C13: W/(m²·K) | D13: nur die beiden Uebergangswiderstaende; Blech vernachlaessigbar
A14: Verlustkoeffizient | B14: ='06-Klima'!$B$13*'03-Modul'!$B$35 -> 4.185088 | C14: W/K | D14: U-Wert x Huellflaeche
A15: Temperaturanstieg ueber Umgebung | B15: ='06-Klima'!$B$10/'06-Klima'!$B$14 -> 3.8541603 | C15: K | D15: Waermelast / Verlustkoeffizient
A16: Sich einstellende Temperatur | B16: ='01-Eingaben'!$B$50+'06-Klima'!$B$15 -> 23.85416 | C16: °C | D16: Umgebung plus Anstieg
A17: Stufe 2 — gedaemmt
A18: Groesse | B18: Wert | C18: Einheit | D18: Herleitung
A19: U-Wert der Wand | B19: =1/(1/'01-Eingaben'!$B$39+'01-Eingaben'!$B$37/1000/'01-Eingaben'!$B$38+1/'01-Eingaben'!$B$40) -> 1.3333333 | C19: W/(m²·K) | D19: Reihenschaltung inkl. Daemmschicht
A20: Verlustkoeffizient | B20: ='06-Klima'!$B$19*'03-Modul'!$B$35 -> 1.3950293 | C20: W/K | D20: U-Wert x Huellflaeche
A21: Temperaturanstieg ueber Umgebung | B21: ='06-Klima'!$B$10/'06-Klima'!$B$20 -> 11.562481 | C21: K | D21: Waermelast / Verlustkoeffizient
A22: Sich einstellende Temperatur | B22: ='01-Eingaben'!$B$50+'06-Klima'!$B$21 -> 31.562481 | C22: °C | D22: Umgebung plus Anstieg
A23: Zusaetzlicher Anstieg durch Daemmung | B23: ='06-Klima'!$B$21-'06-Klima'!$B$15 -> 7.7083206 | C23: K | D23: so viel waermer wird das Modul durch den Liner
A24: Lueftungsbedarf zur Waermeabfuhr
A25: Groesse | B25: Wert | C25: Einheit | D25: Herleitung
A26: Volumenstrom Stufe 1 | B26: =IF('01-Eingaben'!$B$51<='01-Eingaben'!$B$50,0,MAX(0,'06-Klima'!$B$10-'06-Klima'!$B$14*('01-Eingaben'!$B$51-'01-Eingaben'!$B$50))/(1.2*1005*('01-Eingaben'!$B$51-'01-Eingaben'!$B$50))*3600) -> 11.581827 | C26: m³/h | D26: Q = Massenstrom x cp x dT
A27: Volumenstrom Stufe 2 | B27: =IF('01-Eingaben'!$B$51<='01-Eingaben'!$B$50,0,MAX(0,'06-Klima'!$B$10-'06-Klima'!$B$20*('01-Eingaben'!$B$51-'01-Eingaben'!$B$50))/(1.2*1005*('01-Eingaben'!$B$51-'01-Eingaben'!$B$50))*3600) -> 19.91036 | C27: m³/h | D27: identische Rechnung mit gedaemmtem U-Wert
A28: Luftwechselrate Stufe 2 | B28: =IF('03-Modul'!$B$48=0,0,'06-Klima'!$B$27/'03-Modul'!$B$48) -> 383.46615 | C28: 1/h | D28: Volumenstrom / Modulvolumen
A29: Bewertung Luftwechsel | B29: =IF('06-Klima'!$B$28<10,"gering — Feuchte im Modul gut haltbar",IF('06-Klima'!$B$28<100,"mittel — Feuchte folgt teilweise der Raumluft","hoch — Feuchte praktisch gleich Raumluft")) -> hoch — Feuchte praktisch gleich Raumluft | D29: Temperaturregelung ueber Luft kostet Feuchtekontrolle
A30: Heizbedarf Stufe 2 | B30: =MAX(0,'06-Klima'!$B$20*('01-Eingaben'!$B$51-'01-Eingaben'!$B$50)-'06-Klima'!$B$10) -> 0 | C30: W | D30: nur relevant bei kalter Umgebung
A31: Heizmatte ausreichend? | B31: =IF('06-Klima'!$B$30<='01-Eingaben'!$B$54,"ok","Heizleistung erhoehen oder Daemmung verstaerken") -> ok
A32: Stufe 2b — nur Boden und Decke gedaemmt
A33: Groesse | B33: Wert | C33: Einheit | D33: Herleitung
A34: Verlustkoeffizient | B34: ='06-Klima'!$B$19*'03-Modul'!$B$38+'06-Klima'!$B$13*'03-Modul'!$B$39 -> 3.1767893 | C34: W/K | D34: gedaemmte Horizontalflaechen plus offene Seitenwaende
A35: Temperaturanstieg ueber Umgebung | B35: ='06-Klima'!$B$10/'06-Klima'!$B$34 -> 5.0774535 | C35: K | D35: Waermelast / Verlustkoeffizient
A36: Sich einstellende Temperatur | B36: ='01-Eingaben'!$B$50+'06-Klima'!$B$35 -> 25.077453 | C36: °C | D36: Umgebung plus Anstieg
A37: Volumenstrom | B37: =IF('01-Eingaben'!$B$51<='01-Eingaben'!$B$50,0,MAX(0,'06-Klima'!$B$10-'06-Klima'!$B$34*('01-Eingaben'!$B$51-'01-Eingaben'!$B$50))/(1.2*1005*('01-Eingaben'!$B$51-'01-Eingaben'!$B$50))*3600) -> 14.591674 | C37: m³/h | D37: identische Rechnung mit gemischtem U-Wert
A38: Kopplung zwischen zwei Etagen — der eigentliche Zweck der Daemmung
A39: Groesse | B39: Wert | C39: Einheit | D39: Herleitung
A40: Kopplungsanteil Stufe 1 | B40: ='06-Klima'!$B$13*'03-Modul'!$B$36*2/'06-Klima'!$B$14 -> 0.36138977 | C40: - | D40: Waermestrom ueber Boden und Decke / Gesamtverlust
A41: Kopplungsanteil Stufe 2 | B41: ='06-Klima'!$B$19*'03-Modul'!$B$36*2/'06-Klima'!$B$20 -> 0.36138977 | C41: - | D41: identische Rechnung mit gedaemmtem U-Wert
A42: Verschiebung je 10 K Nachbardifferenz, Stufe 1 | B42: ='06-Klima'!$B$40*10 -> 3.6138977 | C42: K | D42: so stark zieht die Nachbaretage
...

Sheet 07-Wasser
A1: Wasser, Ventile, Reservoir
A3: Bedarf
A4: Groesse | B4: Wert | C4: Einheit | D4: Herleitung
A5: Tagesbedarf je Modul | B5: ='01-Eingaben'!$B$57*'03-Modul'!$B$21 -> 0.114048 | C5: l/Tag | D5: spezifischer Bedarf x Anbauflaeche
A6: Tagesbedarf gesamt | B6: ='07-Wasser'!$B$5*'01-Eingaben'!$B$96 -> 0.114048 | C6: l/Tag | D6: je Modul x Etagenzahl
A7: Menge je Zyklus und Modul | B7: ='07-Wasser'!$B$5*1000/'01-Eingaben'!$B$58 -> 28.512 | C7: ml | D7: Tagesbedarf / Zyklen
A8: Ventiloeffnungszeit je Zyklus | B8: ='07-Wasser'!$B$7/('01-Eingaben'!$B$59*1000/3600) -> 5.13216 | C8: s | D8: Menge / effektiver Duesendurchsatz
A9: Bewertung Schaltzeit | B9: =IF('07-Wasser'!$B$8<2,"sehr kurz — Ventiltraegheit dominiert, Zyklen reduzieren",IF('07-Wasser'!$B$8>30,"lang — Staunaessegefahr","praktikabel")) -> praktikabel | D9: Unter 2 s ist die Dosierung nicht mehr reproduzierbar
A10: Zentralversorgung
A11: Groesse | B11: Wert | C11: Einheit | D11: Herleitung
A12: Anzahl Magnetventile | B12: ='01-Eingaben'!$B$96 -> 1 | C12: Stk | D12: eines je Modul — eine Pumpe versorgt alle
A13: Erforderliches Reservoir (alle Racks am Schrankpaar) | B13: ='07-Wasser'!$B$6*'01-Eingaben'!$B$60*'01-Eingaben'!$B$95 -> 0.798336 | C13: l | D13: Tagesbedarf je Rack x Autonomie x Racks je Schrankpaar
A14: Nutzbares Reservoirvolumen | B14: =IF('01-Eingaben'!$B$165=2,'01-Eingaben'!$B$166,'01-Eingaben'!$B$32*'01-Eingaben'!$B$91*'01-Eingaben'!$B$33/1000000*0.6) -> 20 | C14: l | D14: separater Behaelter oder Nasszone im Schrank (60 % nutzbar)
A15: Passt das Reservoir? | B15: =IF('07-Wasser'!$B$14>='07-Wasser'!$B$13,"ok","zu klein: Nasszone hoeher oder Autonomie senken") -> ok | D15: Rueckkopplung in die Geometrie
A16: Moegliche Autonomie | B16: =IF('07-Wasser'!$B$6=0,0,'07-Wasser'!$B$14/'07-Wasser'!$B$6) -> 175.36476 | C16: Tage | D16: vorhandenes Volumen / Tagesbedarf
A17: Moegliche Autonomie | B17: ='07-Wasser'!$B$14/('07-Wasser'!$B$6*'01-Eingaben'!$B$95) -> 175.36476 | D17: Schrankvolumen / (Tagesbedarf je Rack x Racks je Schrankpaar)
A18: Groesse | B18: Wert | C18: Einheit | D18: Herleitung
A19: Substratvolumen je Charge gesamt | B19: ='04-Rack'!$B$18*10000*'01-Eingaben'!$B$19/10/1000 -> 2.8512 | C19: l | D19: Flaeche x Hoehe

Sheet 08-Elektrik
A1: Leistungsbilanz und Bus
A3: Je Modul
A4: Groesse | B4: Wert | C4: Einheit | D4: Herleitung
A5: Dauerlast je Modul | B5: ='05-Licht'!$B$12+'01-Eingaben'!$B$53+'01-Eingaben'!$B$66 -> 17.1 | C5: W | D5: LED, Luefter, Sensorik
A6: Spitzenlast je Modul | B6: ='08-Elektrik'!$B$5+'01-Eingaben'!$B$67 -> 21.1 | C6: W | D6: zusaetzlich Ventil offen
A7: Gesamtes Rack
A8: Groesse | B8: Wert | C8: Einheit | D8: Herleitung
A9: Dauerlast gesamt | B9: ='08-Elektrik'!$B$5*'01-Eingaben'!$B$96+'01-Eingaben'!$B$65 -> 18.1 | C9: W | D9: alle Module plus Steuerung
A10: Spitzenlast gesamt | B10: ='08-Elektrik'!$B$9+'01-Eingaben'!$B$68+'01-Eingaben'!$B$67 -> 30.1 | C10: W | D10: Annahme: nur ein Ventil gleichzeitig offen
A11: Hinweis Bewaesserungsstrategie | B11: ="Module nacheinander bewaessern, nicht gleichzeitig — haelt die Spitzenlast konstant" -> Module nacheinander bewaessern, nicht gleichzeitig — haelt die Spitzenlast konstant | D11: gilt unabhaengig von der Etagenzahl
A12: Strom im 24-V-Kreis | B12: =('05-Licht'!$B$13+'01-Eingaben'!$B$53*'01-Eingaben'!$B$96+'01-Eingaben'!$B$68+'01-Eingaben'!$B$67)/'01-Eingaben'!$B$63 -> 1.2041667 | C12: A | D12: P / U
A13: Netzteil Leistungskreis | B13: =ROUNDUP('08-Elektrik'!$B$12*(1+'01-Eingaben'!$B$69)*10,0)/10 -> 1.6 | C13: A | D13: Strom mit Reserve, auf 0,1 A aufgerundet
A14: Netzteil Logikkreis | B14: =ROUNDUP(('01-Eingaben'!$B$65+'01-Eingaben'!$B$66*'01-Eingaben'!$B$96)/'01-Eingaben'!$B$64*(1+'01-Eingaben'!$B$69)*10,0)/10 -> 0.4 | C14: A | D14: Strom mit Reserve
A15: Energiebedarf je Tag | B15: ='05-Licht'!$B$13*'01-Eingaben'!$B$45+('01-Eingaben'!$B$53+'01-Eingaben'!$B$66)*'01-Eingaben'!$B$96*24+'01-Eingaben'!$B$65*24+('01-Eingaben'!$B$68+'01-Eingaben'!$B$67)*'01-Eingaben'!$B$96*'01-Eingaben'!$B$58*'07-Wasser'!$B$8/3600 -> 311.26843 | C15: Wh | D15: je Verbraucher mit seiner Laufzeit
A16: Bus und Adressierung
A17: Groesse | B17: Wert | C17: Einheit | D17: Herleitung
A18: Benoetigte Schaltkanaele | B18: =2*'01-Eingaben'!$B$96+1 -> 3 | C18: Stk | D18: LED und Ventil je Modul plus Zentralpumpe
A19: Benoetigte Analogkanaele | B19: ='01-Eingaben'!$B$96 -> 1 | C19: Stk | D19: ein Substratfeuchtesensor je Modul
A20: Direkt am ESP32 moeglich? | B20: =IF(2*'01-Eingaben'!$B$96+1<=8,"ja — GPIO reichen noch","nein — Portexpander noetig") -> ja — GPIO reichen noch | D20: ESP32 hat begrenzt nutzbare GPIO
A21: SHT31 direkt adressierbar? | B21: =IF('01-Eingaben'!$B$96<=2,"ja — zwei I2C-Adressen verfuegbar","nein — I2C-Multiplexer TCA9548A noetig") -> ja — zwei I2C-Adressen verfuegbar | D21: SHT31 kennt nur die Adressen 0x44 und 0x45
A22: Empfohlene Architektur | B22: =IF('01-Eingaben'!$B$96<=2,"Zentralsteuerung direkt am ESP32","Zentral-ESP32 mit I2C-Expandern, oder ein ESP32 je Modul am Bus") -> Zentralsteuerung direkt am ESP32 | D22: Ein Controller je Modul macht Module echt eigenstaendig

Sheet 09-Ertrag
A1: Saatbedarf und Ertrag
A3: Je Tray und Modul
A4: Groesse | B4: Wert | C4: Einheit | D4: Herleitung
A5: Saatgut je Tray | B5: ='03-Modul'!$B$13*'01-Eingaben'!$B$73 -> 2.94624 | C5: g | D5: Trayflaeche x Saatdichte
A6: Ernte je Tray | B6: ='03-Modul'!$B$13*'01-Eingaben'!$B$72 -> 41.8176 | C6: g | D6: Trayflaeche x Ertragsdichte
A7: Ernte je Modul und Charge | B7: ='09-Ertrag'!$B$6*'01-Eingaben'!$B$7 -> 250.9056 | C7: g | D7: je Tray x Trays je Etage
A8: Gesamtes Rack
A9: Groesse | B9: Wert | C9: Einheit | D9: Herleitung
A10: Saatgut je Charge gesamt | B10: ='09-Ertrag'!$B$5*'04-Rack'!$B$20 -> 17.67744 | C10: g | D10: je Tray x Trays gesamt
A11: Ernte je Charge gesamt | B11: ='09-Ertrag'!$B$6*'04-Rack'!$B$20 -> 250.9056 | C11: g | D11: je Tray x Trays gesamt
A12: Portionen a 10 g | B12: ='09-Ertrag'!$B$11/10 -> 25.09056 | C12: Stk | D12: typische Garniturmenge je Teller
A13: Chargen je Jahr | B13: =365/('01-Eingaben'!$B$74+'01-Eingaben'!$B$75) -> 21.470588 | C13: 1/Jahr | D13: 365 / (Kulturdauer + Ruestzeit)
A14: Jahresertrag | B14: ='09-Ertrag'!$B$11*'09-Ertrag'!$B$13/1000 -> 5.3870908 | C14: kg | D14: je Charge x Chargen
A15: Jahresertrag je Stellflaeche | B15: ='09-Ertrag'!$B$14/'04-Rack'!$B$15 -> 19.055857 | C15: kg/m²/Jahr | D15: das eigentliche Argument fuer das Rack
A16: Gleichzeitig fuehrbare Sorten | B16: ='04-Rack'!$B$20 -> 6 | C16: Stk | D16: jedes Tray kann eine eigene Sorte tragen

Sheet 10-Kosten
A1: Kosten — nach Ausbaustufe getrennt
A3: Modul in Stufe 1 (einschalig)
A4: Position | B4: Kosten | C4: Einheit | D4: Menge x Preis
A5: Blech | B5: ='03-Modul'!$B$51*'13-Zuschnitt'!$B$47 -> 153.25248 | C5: EUR | D5: Zuschnittbedarf x effektivem Blechpreis (13-Zuschnitt Zeile 47)
A6: GN-Behaelter | B6: ='01-Eingaben'!$B$7*'01-Eingaben'!$B$81 -> 54 | C6: EUR | D6: Trays je Etage x Stueckpreis
A7: LED-Streifen | B7: ='05-Licht'!$B$9*'01-Eingaben'!$B$82 -> 27.5 | C7: EUR | D7: Laenge x Preis je m
A8: Elektronik | B8: ='01-Eingaben'!$B$83 -> 28 | C8: EUR | D8: Pauschale je Modul
A9: Summe Modul Stufe 1 | B9: ='10-Kosten'!$B$5+'10-Kosten'!$B$6+'10-Kosten'!$B$7+'10-Kosten'!$B$8 -> 262.75248 | C9: EUR | D9: Grenzkosten einer einschaligen Etage
A10: Nachruestsatz je Modul
A11: Position | B11: Kosten | C11: Einheit | D11: Menge x Preis
A12: Liner-Blech | B12: ='03-Modul'!$B$37*(1+'01-Eingaben'!$B$41)*'13-Zuschnitt'!$B$47 -> 86.648544 | C12: EUR | D12: Innenschale x Preis je m²
A13: Daemmstoff | B13: ='03-Modul'!$B$53*'01-Eingaben'!$B$80 -> 2.2601472 | C13: EUR | D13: Volumen x Preis je m³
A14: Nachruestsatz Volldaemmung | B14: ='10-Kosten'!$B$12+'10-Kosten'!$B$13 -> 88.908691 | C14: EUR | D14: alle sechs Flaechen
A15: Liner-Blech nur horizontal | B15: ='03-Modul'!$B$40*(1+'01-Eingaben'!$B$41)*'13-Zuschnitt'!$B$47 -> 31.611384 | C15: EUR | D15: Boden und Decke x Preis je m²
A16: Daemmstoff nur horizontal | B16: ='03-Modul'!$B$55*'01-Eingaben'!$B$80 -> 0.8202432 | C16: EUR | D16: Volumen x Preis je m³
A17: Nachruestsatz Teildaemmung | B17: ='10-Kosten'!$B$15+'10-Kosten'!$B$16 -> 32.431627 | C17: EUR | D17: nur Boden und Decke — die wirksame Variante
A18: Modul Stufe 2 gesamt | B18: ='10-Kosten'!$B$9+'10-Kosten'!$B$14 -> 351.66117 | C18: EUR | D18: Stufe 1 plus Nachruestsatz
A19: Aufschlag durch Daemmung | B19: ='10-Kosten'!$B$14/'10-Kosten'!$B$9 -> 0.33837431 | C19: - | D19: Anteil an den Modulkosten
A20: Rack und Zentraltechnik (einmalig)
A21: Position | B21: Kosten | C21: Einheit | D21: Menge x Preis
A22: Staenderwerk | B22: ='15-Tragstruktur'!$B$56 -> 126.36637 | C22: EUR | D22: Rohr, Auflageschienen und Verband — siehe 15-Tragstruktur
A23: Blech Rueckwand | B23: ='04-Rack'!$B$25*'13-Zuschnitt'!$B$47 -> 0 | C23: EUR | D23: Flaeche x effektivem Blechpreis
A24: Zentralelektronik (im Schrankpaar) | B24: ='01-Eingaben'!$B$84 -> 60 | C24: EUR | D24: Pauschale je Schrankpaar, nicht je Rack
A25: Summe Rack (je Rack) | B25: ='10-Kosten'!$B$22+'10-Kosten'!$B$23 -> 126.36637 | C25: EUR | D25: Staenderwerk und Rueckwand — faellt je Rack an
A26: Aktueller Ausbaustand
A27: Position | B27: Kosten | C27: Einheit | D27: Herleitung
A28: Investition jetzt | B28: ='10-Kosten'!$B$25+'10-Kosten'!$B$48+'10-Kosten'!$B$18*'01-Eingaben'!$B$23+'10-Kosten'!$B$9*('01-Eingaben'!$B$96-'01-Eingaben'!$B$23) -> 529.84886 | C28: EUR | D28: Rack + Schrankanteil + Module in ihrer jeweiligen Stufe
A29: Offene Nachruestung | B29: ='10-Kosten'!$B$14*('01-Eingaben'!$B$96-'01-Eingaben'!$B$23) -> 88.908691 | C29: EUR | D29: spaeter faellig, wenn alle Module gedaemmt werden
A30: Vollausbau gesamt | B30: ='10-Kosten'!$B$28+'10-Kosten'!$B$29 -> 618.75755 | C30: EUR | D30: Endzustand alle Etagen gedaemmt
A31: Aufschub durch Stufenbau | B31: ='10-Kosten'!$B$29 -> 88.908691 | C31: EUR | D31: dieser Betrag faellt jetzt nicht an
A32: Verbrauch je Charge
A33: Position | B33: Kosten | C33: Einheit | D33: Herleitung
A34: Substrat | B34: ='07-Wasser'!$B$19*'01-Eingaben'!$B$85 -> 1.71072 | C34: EUR | D34: Volumen x Preis je l
A35: Saatgut | B35: ='09-Ertrag'!$B$10/1000*'01-Eingaben'!$B$86 -> 1.0606464 | C35: EUR | D35: Menge x Preis je kg
A36: Verbrauchskosten je Charge | B36: ='10-Kosten'!$B$34+'10-Kosten'!$B$35 -> 2.7713664 | C36: EUR | D36: Substrat und Saatgut
A37: Verbrauchskosten je 100 g Ernte | B37: ='10-Kosten'!$B$36/'09-Ertrag'!$B$11*100 -> 1.1045455 | C37: EUR | D37: laufende Kosten / Erntemenge
A38: Investition je m² Anbauflaeche | B38: ='10-Kosten'!$B$28/'04-Rack'!$B$18 -> 4645.8408 | C38: EUR/m² | D38: Vergleichsmassstab ueber Etagenzahl und Modulgroesse hinweg
A39: Nicht enthalten | B39: Maschinenstunden fuer Wasserstrahl, Schweissen, Sandstrahlen
B40: Eigenleistung; Strom je Charge ueber 08-Elektrik separat bewertbar
A42: Externe Technikschraenke (je Schrankpaar)
...

Sheet 11-Massen-Statik
A1: Massen und Standsicherheit
A2: Rechnet die Traglast und die Kippsicherheit — beides bisher nicht im Modell enthalten.
A4: Massen je Baugruppe
A5: Groesse | B5: Wert | C5: Einheit | D5: Herleitung
A6: Blech je Modul (netto, ohne Verschnitt) | B6: ='03-Modul'!$B$66*'01-Eingaben'!$B$36/1000*'01-Eingaben'!$B$99 -> 10.612389 | C6: kg | D6: verbautes Blech x Blechstaerke x Dichte — Verschnitt landet im Schrott
A7: GN-Behaelter je Modul | B7: ='01-Eingaben'!$B$7*'01-Eingaben'!$B$101 -> 1.8 | C7: kg | D7: Trays je Etage x Stueckmasse
A8: Substrat nass je Modul | B8: ='07-Wasser'!$B$19/'01-Eingaben'!$B$96*'01-Eingaben'!$B$102 -> 2.8512 | C8: kg | D8: Volumen je Modul x Dichte
A9: Einbauten je Modul | B9: ='01-Eingaben'!$B$103 -> 1.5 | C9: kg | D9: Pauschale
A10: Masse eines bestueckten Moduls | B10: ='11-Massen-Statik'!$B$6+'11-Massen-Statik'!$B$7+'11-Massen-Statik'!$B$8+'11-Massen-Statik'!$B$9 -> 16.763589 | C10: kg | D10: Summe — das traegt eine Traverse
A11: Staenderwerk | B11: ='15-Tragstruktur'!$B$55 -> 23.479247 | C11: kg | D11: Rohr, Auflageschienen und Verband — siehe 15-Tragstruktur
A12: Rueckwandblech (netto) | B12: ='04-Rack'!$B$25/(1+'01-Eingaben'!$B$41)*'01-Eingaben'!$B$36/1000*'01-Eingaben'!$B$99 -> 0 | C12: kg | D12: Verschnitt herausgerechnet
A13: Rack leer | B13: ='11-Massen-Statik'!$B$11+'11-Massen-Statik'!$B$12 -> 23.479247 | C13: kg | D13: ohne Module
A14: Rack voll bestueckt | B14: ='11-Massen-Statik'!$B$13+'11-Massen-Statik'!$B$10*'01-Eingaben'!$B$96 -> 40.242836 | C14: kg | D14: mit den bestueckten Modulen
A16: Standsicherheit
A17: Groesse | B17: Wert | C17: Einheit | D17: Herleitung
A18: Schwerpunkthoehe Staenderwerk | B18: ='04-Rack'!$B$14/2 -> 860 | C18: mm | D18: gleichmaessig verteilte Masse
A19: Schwerpunkthoehe der Module | B19: ='03-Modul'!$B$34/2+'04-Rack'!$B$7+'01-Eingaben'!$B$27+'01-Eingaben'!$B$26+('04-Rack'!$B$39-1)/2*'04-Rack'!$B$5 -> 282 | C19: mm | D19: Mitte der belegten Ebenen — bei mehreren Spalten fuellt eine Ebene mehr Module
A20: Schwerpunkt gesamt | B20: =('11-Massen-Statik'!$B$13*'11-Massen-Statik'!$B$18+'11-Massen-Statik'!$B$10*'01-Eingaben'!$B$96*'11-Massen-Statik'!$B$19)/'11-Massen-Statik'!$B$14 -> 619.22785 | C20: mm | D20: massengewichtet
A21: Kippwinkel um die schmalste Seite | B21: =DEGREES(ATAN((MIN('04-Rack'!$B$12,'04-Rack'!$B$13)/2)/'11-Massen-Statik'!$B$20)) -> 22.540064 | C21: Grad | D21: arctan(halbe kleinste Grundrisskante / Schwerpunkthoehe) — Breite ODER Tiefe, je nachdem was kleiner ist
A22: Bewertung Standsicherheit | B22: =IF('11-Massen-Statik'!$B$21>=20,"ok — frei stehend vertretbar","gering — Rack an der Wand sichern") -> ok — frei stehend vertretbar | D22: Richtwert: unter 20 Grad gehoert ein hohes, schmales Regal an die Wand
A24: Traglast je Traverse
A25: Groesse | B25: Wert | C25: Einheit | D25: Herleitung
A26: Auslegungslast je Etagenauflage | B26: ='14-Modulmasse'!$B$38 -> 36.961707 | C26: kg | D26: schwerste Ausbaustufe mit Sicherheitsbeiwert — nicht die Ist-Masse
A27: Stuetzweite der Traverse | B27: =IF('01-Eingaben'!$B$151=1,'04-Rack'!$B$11,'15-Tragstruktur'!$B$9) -> 490 | C27: mm | D27: lichte Breite beim Vollring, Reihentiefe bei der Auflageschiene
A28: Flaechentraegheitsmoment des tragenden Profils | B28: =IF('01-Eingaben'!$B$151=1,('01-Eingaben'!$B$26^4-('01-Eingaben'!$B$26-2*'01-Eingaben'!$B$100)^4)/12,'15-Tragstruktur'!$B$21) -> 2238.6366 | C28: mm^4 | D28: Quadratrohr oder abgekanteter Winkel, je nach Bauart
A29: Durchbiegung im Auslegungsfall | B29: =IF('01-Eingaben'!$B$151=1,B26*9.81*B27^3/(48*200000*B28*2),'15-Tragstruktur'!$B$23) -> 0.62030382 | C29: mm | D29: Vollring: Einzellast in Feldmitte. Auflageschiene: Gleichlast ueber die Auflagelaenge — siehe 15-Tragstruktur
A30: Bewertung Durchbiegung | B30: =IF(B29<=B27/500,"ok — unter L/500","zu weich — Profil vergroessern") -> ok — unter L/500 | D30: L/500 ist streng; fuer ein Regal genuegt es deutlich
A32: Hinweis | B32: Massen der GN-Behaelter und Einbauten sind Schaetzwerte — nach der Beschaffung nachwiegen.

Sheet 12-Installationsgrenzen
A1: Wie weit duerfen Elektronik- und Hydraulikschrank vom Rack entfernt stehen?
A2: Beide Schraenke sind frei platzierbar — aber nicht beliebig weit weg.
A4: Elektrisch: Spannungsabfall im 24-V-Kreis
A5: Groesse | B5: Wert | C5: Einheit | D5: Herleitung
A6: Strom im Leistungskreis | B6: ='08-Elektrik'!$B$12 -> 1.2041667 | C6: A | D6: aus der Leistungsbilanz
A7: Zulaessiger Spannungsabfall | B7: ='01-Eingaben'!$B$63*'01-Eingaben'!$B$107 -> 0.72 | C7: V | D7: Anteil der Kreisspannung
A8: Maximale einfache Leitungslaenge | B8: ='12-Installationsgrenzen'!$B$7*'01-Eingaben'!$B$106/(2*'01-Eingaben'!$B$108*'12-Installationsgrenzen'!$B$6) -> 25.625309 | C8: m | D8: U = I x R, Hin- und Rueckleiter
A9: Bewertung | B9: =IF('12-Installationsgrenzen'!$B$8>=5,"unkritisch — Schrank kann im Nebenraum stehen",IF('12-Installationsgrenzen'!$B$8>=2,"Schrank in Racknähe halten","Querschnitt erhoehen")) -> unkritisch — Schrank kann im Nebenraum stehen
A11: Hydraulisch: Foerderhoehe und Rohrreibung
A12: Groesse | B12: Wert | C12: Einheit | D12: Herleitung
A13: Statische Hoehe bis zur obersten Etage | B13: =('04-Rack'!$B$14-'01-Eingaben'!$B$26)/1000 -> 1.69 | C13: m | D13: das Wasser muss bis unter die Rackdecke
A14: Verbleibend fuer Reibung | B14: ='01-Eingaben'!$B$110-'12-Installationsgrenzen'!$B$13 -> 1.31 | C14: m | D14: Foerderhoehe minus statische Hoehe
A15: Volumenstrom je Modul | B15: ='01-Eingaben'!$B$59/3600/1000 -> 5.5555556e-06 | C15: m³/s | D15: effektiver Duesendurchsatz
A16: Stroemungsgeschwindigkeit | B16: ='12-Installationsgrenzen'!$B$15/(PI()*('01-Eingaben'!$B$109/2000)^2) -> 0.19648758 | C16: m/s | D16: Q / Querschnitt
A17: Reynoldszahl | B17: =1000*'12-Installationsgrenzen'!$B$16*'01-Eingaben'!$B$109/1000/'01-Eingaben'!$B$111 -> 1178.9255 | C17: - | D17: unter 2300 laminar — dann gilt Hagen-Poiseuille
A18: Druckverlust je Meter Schlauch | B18: =128*'01-Eingaben'!$B$111*'12-Installationsgrenzen'!$B$15/(PI()*('01-Eingaben'!$B$109/1000)^4)/9810 -> 0.017803836 | C18: m/m | D18: Hagen-Poiseuille, umgerechnet in Wassersaeule
A19: Maximale Schlauchlaenge | B19: ='12-Installationsgrenzen'!$B$14/'12-Installationsgrenzen'!$B$18 -> 73.579649 | C19: m | D19: Restfoerderhoehe / Verlust je Meter
A20: Bewertung | B20: =IF('12-Installationsgrenzen'!$B$14<=0,"FEHLER: Pumpe schafft die Rackhoehe nicht",IF('12-Installationsgrenzen'!$B$19>=10,"unkritisch — die Rackhoehe dominiert, nicht die Schlauchlaenge","Schlauchlaenge begrenzt — Durchmesser erhoehen")) -> unkritisch — die Rackhoehe dominiert, nicht die Schlauchlaenge
A22: Hinweis | B22: Die Foerderhoehe der Pumpe ist der harte Grenzwert. Sie steigt nicht mit dem Schlauchdurchmesser.
B23: Bei mehreren Racks am selben Schrankpaar gilt die Rechnung je Strang, nicht in Summe.
A25: Signalleitungen — die eigentliche Grenze
A26: Groesse | B26: Wert | C26: Einheit | D26: Herleitung
A27: Verbleibende Kapazitaet fuer das Kabel | B27: ='01-Eingaben'!$B$122-'01-Eingaben'!$B$124*10 -> 370 | C27: pF | D27: Zulaessig minus Teilnehmerkapazitaet
A28: Maximale I2C-Leitungslaenge | B28: ='12-Installationsgrenzen'!$B$27/'01-Eingaben'!$B$123 -> 3.7 | C28: m | D28: ohne Bus-Extender
A29: Verhaeltnis zur Leistungsleitung | B29: ='12-Installationsgrenzen'!$B$8/'12-Installationsgrenzen'!$B$28 -> 6.9257592 | C29: - | D29: wie viel weiter die Versorgung darf als das Signal
A30: Mit Bus-Extender P82B715 | B30: ='12-Installationsgrenzen'!$B$28*10 -> 37 | C30: m | D30: entkoppelt die Buskapazitaet um Faktor 10
A31: Bewertung | B31: =IF('12-Installationsgrenzen'!$B$28>=5,"Schrank frei platzierbar","Schrank in Racknaehe ODER Bus-Extender ODER Controller je Modul") -> Schrank in Racknaehe ODER Bus-Extender ODER Controller je Modul
A33: Merke | B33: Die Leistungsleitung darf weit, die Signalleitung nicht. Wer nur den
B34: Spannungsabfall rechnet, stellt den Schrank zu weit weg und wundert sich
B35: ueber sporadische Sensorausfaelle.
B36: Analoge Feuchtesensoren sind noch empfindlicher: ueber 2-3 m stoeranfaellig.

Sheet 13-Zuschnitt
A1: Zuschnittsliste — alle Blechteile
A2: Masse in mm, Flaechen in m². Bruttoflaeche enthaelt Ausschnitte als Abfall.
A4: Teil | B4: Breite | C4: Hoehe | D4: Anzahl | E4: Flaeche | F4: Bemerkung
A5: Modul Boden | B5: ='03-Modul'!$B$32 -> 448 | C5: ='03-Modul'!$B$33 -> 422 | D5: =1 -> 1 | E5: =B5*C5*D5/1000000 -> 0.189056 | F5: Huellboden, eben
A6: Modul Decke | B6: ='03-Modul'!$B$32 -> 448 | C6: ='03-Modul'!$B$33 -> 422 | D6: =1 -> 1 | E6: =B6*C6*D6/1000000 -> 0.189056 | F6: traegt die LED-Standoffs
A7: Modul Seitenwand | B7: ='03-Modul'!$B$33-2*'01-Eingaben'!$B$36 -> 420 | C7: ='03-Modul'!$B$34-2*'01-Eingaben'!$B$36 -> 382 | D7: =2 -> 2 | E7: =B7*C7*D7/1000000 -> 0.32088 | F7: mit Linerbolzen
A8: Modul Rueckwand | B8: ='03-Modul'!$B$32-2*'01-Eingaben'!$B$36 -> 446 | C8: ='03-Modul'!$B$34-2*'01-Eingaben'!$B$36 -> 382 | D8: =1 -> 1 | E8: =B8*C8*D8/1000000 -> 0.170372 | F8: Ablauf, Kupplung, Stecker, Luefter
A9: Modul Frontrahmen | B9: ='03-Modul'!$B$32-2*'01-Eingaben'!$B$36 -> 446 | C9: ='03-Modul'!$B$34-2*'01-Eingaben'!$B$36 -> 382 | D9: =1 -> 1 | E9: =B9*C9*D9/1000000 -> 0.170372 | F9: mit Ausschnitt fuer die Klappe
A10: Frontklappe | B10: ='03-Modul'!$B$26+2*'01-Eingaben'!$B$117 -> 428 | C10: ='03-Modul'!$B$28+2*'01-Eingaben'!$B$117 -> 364 | D10: =1 -> 1 | E10: =B10*C10*D10/1000000 -> 0.155792 | F10: ueberlappt umlaufend
A11: Modulboden geneigt | B11: ='03-Modul'!$B$32-2*'01-Eingaben'!$B$36 -> 446 | C11: ='03-Modul'!$B$33-2*'01-Eingaben'!$B$36 -> 420 | D11: =1 -> 1 | E11: =B11*C11*D11/1000000 -> 0.18732 | F11: 2 Grad laengs, 1 Grad quer
A12: Auflageschiene aussen | B12: =2*'01-Eingaben'!$B$12+'01-Eingaben'!$B$114 -> 38 | C12: ='03-Modul'!$B$27 -> 378 | D12: =2 -> 2 | E12: =B12*C12*D12/1000000 -> 0.028728 | F12: U-Profil, 2 Kantungen
A13: Auflageschiene innen | B13: =2*'01-Eingaben'!$B$12+2*'01-Eingaben'!$B$114+'01-Eingaben'!$B$10 -> 48 | C13: ='03-Modul'!$B$27 -> 378 | D13: ='01-Eingaben'!$B$8-1 -> 1 | E13: =B13*C13*D13/1000000 -> 0.018144 | F13: U-Profil, traegt zwei Reihen
A14: Quertraeger | B14: =2*'01-Eingaben'!$B$12+'01-Eingaben'!$B$116 -> 50 | C14: ='03-Modul'!$B$26 -> 404 | D14: =2 -> 2 | E14: =B14*C14*D14/1000000 -> 0.0404 | F14: U-Profil, tragen die Schienen
A15: Anschlag laengs | B15: ='01-Eingaben'!$B$115 -> 8 | C15: ='03-Modul'!$B$27 -> 378 | D15: =2 -> 2 | E15: =B15*C15*D15/1000000 -> 0.006048 | F15: seitliche Fuehrung
A16: Anschlag quer | B16: ='01-Eingaben'!$B$115 -> 8 | C16: ='03-Modul'!$B$19 -> 354 | D16: =1 -> 1 | E16: =B16*C16*D16/1000000 -> 0.002832 | F16: Endanschlag hinten
A17: Standoff | B17: ='01-Eingaben'!$B$116 -> 20 | C17: ='01-Eingaben'!$B$37-'01-Eingaben'!$B$36 -> 19 | D17: =4 -> 4 | E17: =B17*C17*D17/1000000 -> 0.00152 | F17: ueberbrueckt den Freiraum Stufe 1
A18: Summe je Modul (netto) | E18: =SUM(E5:E17) -> 1.48052 | F18: Gegenprobe 03-Modul B66
A20: Rack und Schraenke
A21: Teil | B21: Breite | C21: Hoehe | D21: Anzahl | E21: Flaeche | F21: Bemerkung
A22: Rack Rueckwand | B22: =IF('01-Eingaben'!$B$163=1,'04-Rack'!$B$11,IF('01-Eingaben'!$B$163=2,'01-Eingaben'!$B$164,0)) -> 0 | C22: ='04-Rack'!$B$14 -> 1720 | D22: 1 | E22: =B22*C22*D22/1000000 -> 0 | F22: Breite nach Rueckwandbauart (01-Eingaben Zeile 163)
A23: Elektronikschrank Wand | B23: ='01-Eingaben'!$B$30 -> 300 | C23: ='01-Eingaben'!$B$31 -> 300 | D23: =2 -> 2 | E23: =B23*C23*D23/1000000 -> 0.18 | F23: Front und Rueckseite
A24: Elektronikschrank Deckel | B24: ='01-Eingaben'!$B$30 -> 300 | C24: ='01-Eingaben'!$B$90 -> 150 | D24: =2 -> 2 | E24: =B24*C24*D24/1000000 -> 0.09 | F24: oben und unten
A25: Elektronikschrank Seite | B25: ='01-Eingaben'!$B$31 -> 300 | C25: ='01-Eingaben'!$B$90 -> 150 | D25: =2 -> 2 | E25: =B25*C25*D25/1000000 -> 0.09 | F25: links und rechts
A26: Hydraulikschrank Wand | B26: ='01-Eingaben'!$B$32 -> 300 | C26: ='01-Eingaben'!$B$33 -> 300 | D26: =2 -> 2 | E26: =B26*C26*D26/1000000 -> 0.18 | F26: Front und Rueckseite
A27: Hydraulikschrank Deckel | B27: ='01-Eingaben'!$B$32 -> 300 | C27: ='01-Eingaben'!$B$91 -> 200 | D27: =2 -> 2 | E27: =B27*C27*D27/1000000 -> 0.12 | F27: oben und unten
A28: Hydraulikschrank Seite | B28: ='01-Eingaben'!$B$33 -> 300 | C28: ='01-Eingaben'!$B$91 -> 200 | D28: =2 -> 2 | E28: =B28*C28*D28/1000000 -> 0.12 | F28: links und rechts
A29: Summe Rack und Schraenke | E29: =SUM(E22:E28) -> 0.78
A31: Materialbedarf
A32: Groesse | B32: Wert | C32: Einheit | D32: Herleitung
A33: Teileflaeche gesamt | B33: =E18*'01-Eingaben'!$B$96+E29 -> 2.26052 | C33: m² | D33: Module x Anzahl plus Basis
A34: Ausschnittabfall je Modul | B34: ='03-Modul'!$B$67 -> 0.13736 | C34: m² | D34: Frontoeffnung, wird herausgeschnitten
A35: Zuschnittflaeche gesamt | B35: =B33+B34*'01-Eingaben'!$B$96 -> 2.39788 | C35: m² | D35: Teile plus Ausschnitte
A36: Flaeche einer Blechtafel | B36: ='01-Eingaben'!$B$118*'01-Eingaben'!$B$119/1000000 -> 2 | C36: m² | D36: Standardtafel
A37: Tafeln rechnerisch (ohne Schachtelung) | B37: =ROUNDUP(B35/B36,0) -> 2 | C37: Stk | D37: Zuschnittflaeche / Tafelflaeche, aufgerundet
A38: Tafeln real (Schachtelung 19.08.) | B38: =ROUNDUP(B35/(B36*'01-Eingaben'!$B$168),0) -> 3 | C38: Stk | D38: Zuschnittflaeche / (Tafelflaeche x Schachtelgrad) — bei geaenderter Teilegeometrie neu schachteln
A39: Verschnitt bei Tafelkauf | B39: =1-B33/(B38*B36) -> 0.62324667 | C39: - | D39: 1 - Teileflaeche / Tafelflaeche
A40: Blechkosten bei Tafelkauf | B40: =B38*B36*'01-Eingaben'!$B$78 -> 540 | C40: EUR | D40: Tafeln real x Tafelflaeche x Preis
A41: Blechkosten bei Zuschnitt nach Mass | B41: =B35*(1+'01-Eingaben'!$B$41)*'01-Eingaben'!$B$78 -> 248.18058 | C41: EUR | D41: Zuschnittflaeche x (1+Verschnittzuschlag) x Preis
A42: Differenz der Szenarien | B42: =B40-B41 -> 291.81942 | C42: EUR | D42: im Firmengespraech zu klaeren
A43: Wirksames Beschaffungsszenario
...

Sheet 14-Modulmasse
A1: Masse eines Moduls — Ist-Zustand und Ausbaureserve
A2: Die Modulmasse ist die Auslegungslast der Etagenauflage. Sie waechst mit jedem Ausbauschritt — deshalb wird nicht der Ist-Zustand bemessen, sondern die schwerste absehbare Stufe.
A4: A Ist-Zustand — Stufe 1, wie gebaut
A5: Position | B5: Masse | C5: Einheit | D5: Herleitung
A6: Blech Modul (netto) | B6: ='03-Modul'!$B$66*'01-Eingaben'!$B$36/1000*'01-Eingaben'!$B$99 -> 10.612389 | C6: kg | D6: verbautes Blech x Blechstaerke x Dichte
A7: GN-Behaelter bestueckt | B7: ='01-Eingaben'!$B$7*'01-Eingaben'!$B$101 -> 1.8 | C7: kg | D7: Trays je Etage x Stueckmasse
A8: Substrat nass | B8: ='07-Wasser'!$B$19/'01-Eingaben'!$B$96*'01-Eingaben'!$B$102 -> 2.8512 | C8: kg | D8: Volumen je Modul x Dichte
A9: Einbauten (LED, Luefter, Ventil, Duesen, Kabel) | B9: ='01-Eingaben'!$B$103 -> 1.5 | C9: kg | D9: Pauschale — Gegenprobe in Abschnitt E
A10: Summe Ist-Zustand | B10: =SUM(B6:B9) -> 16.763589 | C10: kg | D10: das traegt die Etagenauflage heute
A12: B Was beim Ausbau dazukommt — jede Zeile fuer sich
A13: Position | B13: Masse | C13: Einheit | D13: Herleitung
A14: Teildaemmung 2b: Liner Boden und Decke | B14: ='03-Modul'!$B$40*'01-Eingaben'!$B$36/1000*'01-Eingaben'!$B$99 -> 2.4128496 | C14: kg | D14: zwei Flaechen Innenschale
A15: Teildaemmung 2b: Schaumglas | B15: ='03-Modul'!$B$55*'01-Eingaben'!$B$138 -> 0.8202432 | C15: kg | D15: Volumen x Dichte
A16: Volldaemmung 2: Liner rundum | B16: ='03-Modul'!$B$37*'01-Eingaben'!$B$36/1000*'01-Eingaben'!$B$99 -> 6.6137536 | C16: kg | D16: sechs Flaechen Innenschale — enthaelt 2b
A17: Volldaemmung 2: Schaumglas | B17: ='03-Modul'!$B$53*'01-Eingaben'!$B$138 -> 2.2601472 | C17: kg | D17: Volumen x Dichte — enthaelt 2b
A18: (Variante) Eigenes Reservoir: Wasser | B18: ='01-Eingaben'!$B$139*'01-Eingaben'!$B$102 -> 0 | C18: kg | D18: verworfen: 5 kg an einem Modul, das gezogen werden muss — siehe Befund 4x
A19: (Variante) Eigenes Reservoir: Behaelter | B19: ='01-Eingaben'!$B$140 -> 0.6 | C19: kg | D19: leer
A20: Dezentraler Controller mit Gehaeuse | B20: ='01-Eingaben'!$B$141 -> 0.25 | C20: kg | D20: Folge aus Befund 4o und 4r
A21: Erweiterte Sensorik | B21: ='01-Eingaben'!$B$142 -> 0.3 | C21: kg | D21: Boden-EC, pH, CO2, Blatttemperatur
A22: Zusatzaktorik | B22: ='01-Eingaben'!$B$143 -> 1.2 | C22: kg | D22: Dosierpumpen, CO2-Ventil, Befeuchter, Heizmatte, zweiter Luefter
A23: Tiefere Trays (65 statt 40 mm) | B23: ='01-Eingaben'!$B$7*2*('03-Modul'!$B$9+'03-Modul'!$B$10)*('01-Eingaben'!$B$144-'01-Eingaben'!$B$6)/1000000*'01-Eingaben'!$B$146/1000*'01-Eingaben'!$B$99 -> 0.471156 | C23: kg | D23: zusaetzliche Mantelflaeche der Behaelter: Umfang x Hoehendifferenz
A24: Mehr Substrat (40 statt 25 mm) | B24: =B8*('01-Eingaben'!$B$145/'01-Eingaben'!$B$19-1) -> 1.71072 | C24: kg | D24: Volumen waechst proportional zur Hoehe
A26: C Ausbauszenarien — kumuliert
A27: Position | B27: Masse | C27: Einheit | D27: Was enthalten ist
A28: S1 Ist-Zustand | B28: =B10 -> 16.763589 | C28: kg | D28: Stufe 1, einschalig, zentrale Steuerung
A29: S2 + Teildaemmung 2b | B29: =B28+B14+B15 -> 19.996681 | C29: kg | D29: die einzige wirksame Daemmvariante, Befund 4d
A30: S3 + Automatisierung | B30: =B29+B20+B21+B22 -> 21.746681 | C30: kg | D30: dezentraler Controller, erweiterte Sensorik und Aktorik
A31: S4 Vollausbau | B31: =B10+B16+B17+B20+B21+B22+B23+B24 -> 29.569365 | C31: kg | D31: Volldaemmung statt 2b, Automatisierung, tiefere Trays, mehr Substrat
A32: V Verworfen: eigenes Reservoir am Modul | B32: =B31+B18+B19 -> 30.169365 | C32: kg | D32: am 21.08. verworfen — Reservoir sitzt separat am Schrank. Zaehlt NICHT in die Auslegungslast
A34: D Auslegungslast je Modulplatz
A35: Position | B35: Masse | C35: Einheit | D35: Herleitung
A36: Schwerste Ausbaustufe | B36: =MAX(B28:B31) -> 29.569365 | C36: kg | D36: Maximum der verfolgten Szenarien — die verworfene Variante V bleibt aussen vor
A37: Sicherheitsbeiwert | B37: ='01-Eingaben'!$B$147 -> 1.25 | C37: - | D37: Zuschlag fuer Unvorhergesehenes
A38: Auslegungslast je Modulplatz | B38: =B36*B37 -> 36.961707 | C38: kg | D38: damit wird die Etagenauflage bemessen
A39: Verhaeltnis zur Ist-Masse | B39: =B38/B10 -> 2.2048803 | C39: - | D39: so viel Luft hat die Konstruktion nach oben
A40: Bewertung | B40: =IF(B39>=2,"reichlich — Modul kann sich verdoppeln",IF(B39>=1.5,"ausreichend","knapp — Ausbaureserve pruefen")) -> reichlich — Modul kann sich verdoppeln
A42: E Gegenprobe zur Einbautenpauschale
A43: Position | B43: Masse | C43: Einheit | D43: Herleitung
A44: LED-Profil und Streifen | B44: ='05-Licht'!$B$9*0.25 -> 0.275 | C44: kg | D44: gewaehlte Streifenlaenge x rund 250 g je Meter Alu-Profil mit Streifen
A45: Luefter, Ventil, Duesen, Spruehleiste | B45: 0.55 | C45: kg | D45: 40-mm-Luefter 0,05 · Ventil 0,25 · Leiste mit Duesen 0,25
...

Sheet 15-Tragstruktur
A1: Tragstruktur — Vollring gegen Fachwerk
A2: Bauart 1 traegt jedes Modul auf einem umlaufenden Ring. Bauart 2 ersetzt die mittleren Ringe durch leichte Auflageschienen und faengt die Aussteifung mit Diagonalen ab.
A4: A Bauteile je Bauart
A5: Groesse | B5: Wert | C5: Einheit | D5: Herleitung
A6: Gewaehlte Bauart | B6: =IF('01-Eingaben'!$B$151=1,"1 — Vollring je Etage","2 — Auflageschienen mit Diagonalverband") -> 2 — Auflageschienen mit Diagonalverband | D6: umgeschaltet in 01-Eingaben Zeile 151
A7: Traversenringe aus Vierkantrohr | B7: =IF('01-Eingaben'!$B$151=1,'01-Eingaben'!$B$22+2,2) -> 2 | C7: Stk | D7: Bauart 2 behaelt nur Boden- und Kopfring
A8: Auflageschienen gesamt | B8: =IF('01-Eingaben'!$B$151=1,0,2*'01-Eingaben'!$B$133*'01-Eingaben'!$B$134*'01-Eingaben'!$B$22) -> 8 | C8: Stk | D8: zwei je Modulplatz, in Auszugsrichtung
A9: Stuetzweite einer Auflageschiene | B9: =('04-Rack'!$B$13-('01-Eingaben'!$B$134+1)*'01-Eingaben'!$B$26)/'01-Eingaben'!$B$134 -> 490 | C9: mm | D9: lichter Abstand zwischen zwei Staenderreihen
A10: Diagonalen im Verband | B10: =IF('01-Eingaben'!$B$151=1,0,4)+IF('01-Eingaben'!$B$163>1,2,0) -> 6 | C10: Stk | D10: zwei je Seitenebene; zwei zusaetzlich in der Rueckebene, wenn dort keine Blechscheibe mehr sitzt
A11: Hoehe der verspannten Ebene | B11: ='04-Rack'!$B$14-'01-Eingaben'!$B$92-2*'01-Eingaben'!$B$26 -> 1625 | C11: mm | D11: zwischen Boden- und Kopfring
A12: Breite der verspannten Ebene | B12: ='04-Rack'!$B$13-2*'01-Eingaben'!$B$26 -> 490 | C12: mm | D12: Racktiefe abzueglich der Staender
A13: Mittlere Laenge einer Diagonale | B13: =IF(B10=0,0,(IF('01-Eingaben'!$B$151=1,0,4)*SQRT(B11^2+B12^2)+IF('01-Eingaben'!$B$163>1,2,0)*SQRT(B11^2+('04-Rack'!$B$11)^2))/B10) -> 1693.9228 | C13: mm | D13: Seitenebenen ueber die Racktiefe, Rueckebene ueber die lichte Breite — gemittelt
A14: Aussteifende Ebenen | B14: =IF('01-Eingaben'!$B$151=1,IF('01-Eingaben'!$B$163=1,"Rahmenwirkung der sechs Ringe plus Rueckwandscheibe","Rahmenwirkung der sechs Ringe plus Diagonalen hinten"),IF('01-Eingaben'!$B$163=1,"Diagonalen seitlich, Rueckwandscheibe hinten","Diagonalen seitlich und hinten")) -> Diagonalen seitlich und hinten | D14: die Vorderseite bleibt immer frei — dort fahren die Module heraus
A15: B Auflageschiene — Nachweis (Bauart 2; bei Bauart 1 traegt der Vollring, Nachweis in 11-Massen-Statik)
A16: Groesse | B16: Wert | C16: Einheit | D16: Herleitung
A17: Auslegungslast je Modulplatz | B17: ='14-Modulmasse'!$B$38 -> 36.961707 | C17: kg | D17: schwerste Ausbaustufe mit Sicherheitsbeiwert
A18: Last je Schiene | B18: =B17*9.81/2 -> 181.29717 | C18: N | D18: zwei Schienen teilen sich das Modul
A19: Querschnittsflaeche Winkel | B19: ='01-Eingaben'!$B$152*'01-Eingaben'!$B$153+'01-Eingaben'!$B$153*('01-Eingaben'!$B$152-'01-Eingaben'!$B$153) -> 57.75 | C19: mm² | D19: gleichschenklig, abgekantet
A20: Schwerpunktabstand von der Auflageflaeche | B20: =('01-Eingaben'!$B$152*'01-Eingaben'!$B$153*'01-Eingaben'!$B$153/2+'01-Eingaben'!$B$153*('01-Eingaben'!$B$152-'01-Eingaben'!$B$153)*('01-Eingaben'!$B$153+('01-Eingaben'!$B$152-'01-Eingaben'!$B$153)/2))/B19 -> 5.5551948 | C20: mm | D20: Flaechenmoment erster Ordnung
A21: Flaechentraegheitsmoment | B21: ='01-Eingaben'!$B$152*'01-Eingaben'!$B$153^3/12+'01-Eingaben'!$B$152*'01-Eingaben'!$B$153*(B20-'01-Eingaben'!$B$153/2)^2+'01-Eingaben'!$B$153*('01-Eingaben'!$B$152-'01-Eingaben'!$B$153)^3/12+'01-Eingaben'!$B$153*('01-Eingaben'!$B$152-'01-Eingaben'!$B$153)*(('01-Eingaben'!$B$153+('01-Eingaben'!$B$152-'01-Eingaben'!$B$153)/2)-B20)^2 -> 2238.6366 | C21: mm⁴ | D21: Steiner an beiden Schenkeln
A22: Widerstandsmoment | B22: =B21/('01-Eingaben'!$B$152-B20) -> 154.97866 | C22: mm³ | D22: auf die gezogene Faser bezogen
A23: Durchbiegung bei Gleichlast | B23: =5*B18*B9^3/(384*200000*B21) -> 0.62030382 | C23: mm | D23: 5FL³/384EI, E = 200 GPa
A24: Grenzwert L/500 | B24: =B9/500 -> 0.98 | C24: mm | D24: strenge Grenze fuer Regale
A25: Bewertung Durchbiegung | B25: =IF(B23<=B24,"ok — unter L/500","zu weich — Schenkel oder Blechstaerke erhoehen") -> ok — unter L/500
A26: Biegemoment | B26: =B18*B9/8 -> 11104.452 | C26: Nmm | D26: Gleichlast, gelenkig gelagert
A27: Biegespannung | B27: =B26/B22 -> 71.651488 | C27: N/mm² | D27: M / W
A28: Sicherheit gegen Streckgrenze | B28: ='01-Eingaben'!$B$162/B27 -> 3.2099822 | C28: - | D28: Streckgrenze / vorhandene Spannung
A29: Bewertung Tragfaehigkeit | B29: =IF(B28>=2,"ok — Sicherheit ueber 2",IF(B28>=1.5,"knapp","nicht ausreichend")) -> ok — Sicherheit ueber 2
A31: C Diagonalverband — Nachweis
A32: Groesse | B32: Wert | C32: Einheit | D32: Herleitung
A33: Masse Rack im Auslegungsfall | B33: ='11-Massen-Statik'!$B$13+B17*'01-Eingaben'!$B$133*'01-Eingaben'!$B$134*'01-Eingaben'!$B$22 -> 171.32607 | C33: kg | D33: leeres Rack plus alle Plaetze mit Auslegungslast
A34: Horizontale Ersatzlast | B34: =B33*9.81*'01-Eingaben'!$B$160 -> 33.614176 | C34: N | D34: Anteil der Gewichtskraft, Schieflage und Anstossen
A35: Zugkraft in einer Diagonale | B35: =B34/2*B13/B12 -> 58.101857 | C35: N | D35: je Seitenebene die Haelfte, umgerechnet auf die Diagonalrichtung
A36: Tragreserve Seil | B36: ='01-Eingaben'!$B$155^2*'01-Eingaben'!$B$156*1000/'01-Eingaben'!$B$161 -> 2133.3333 | C36: N | D36: Bruchkraft / Sicherheitsbeiwert
A37: Tragreserve Flachband | B37: ='01-Eingaben'!$B$159*'01-Eingaben'!$B$153*'01-Eingaben'!$B$162/'01-Eingaben'!$B$161 -> 2875 | C37: N | D37: Querschnitt x Streckgrenze / Sicherheitsbeiwert
A38: Gewaehlte Diagonalart | B38: =IF('01-Eingaben'!$B$154=1,"Stahlseil mit Spannschloss","Flachband aus Blech") -> Flachband aus Blech
A39: Vorhandene Tragreserve | B39: =IF('01-Eingaben'!$B$154=1,B36,B37) -> 2875 | C39: N
A40: Ausnutzung | B40: =B35/B39 -> 0.020209342 | C40: -
A41: Bewertung Verband | B41: =IF(B40<=1,"ok — Verband traegt","zu schwach — Durchmesser oder Bandbreite erhoehen") -> ok — Verband traegt
A43: D Materialbilanz der beiden Bauarten
...

Sheet 16-CAD-Parameter
A1: Parameteruebergabe an die CAD-Dateien
A2: Dieses Blatt ist die Schnittstelle. Das FreeCAD-Makro MikrogruenParameter_Sync liest es direkt aus dieser Datei und schreibt die Werte in jedes offene CAD-Dokument.
A3: NUR Eingangsgroessen. Abgeleitete Masse bleiben im CAD Ausdruecke und werden nicht ueberschrieben. Neue Zeile hier = neuer Parameter im CAD.
A5: Alias im CAD | B5: Quellblatt | C5: Zelle | D5: Wert | E5: Einheit | F5: Bedeutung
A6: tray_L | B6: 03-Modul | C6: B9 | D6: =INDIRECT("'"&B6&"'!"&C6) -> 176 | E6: mm | F6: Traylaenge aus der GN-Norm
A7: tray_B | B7: 03-Modul | C7: B10 | D7: =INDIRECT("'"&B7&"'!"&C7) -> 108 | E7: mm | F7: Traybreite aus der GN-Norm
A8: tray_h | B8: 01-Eingaben | C8: B6 | D8: =INDIRECT("'"&B8&"'!"&C8) -> 40 | E8: mm | F8: Trayhoehe
A9: n_trays | B9: 01-Eingaben | C9: B7 | D9: =INDIRECT("'"&B9&"'!"&C9) -> 6 | F9: Trays je Etage
A10: n_spalten | B10: 01-Eingaben | C10: B8 | D10: =INDIRECT("'"&B10&"'!"&C10) -> 2 | F10: Spalten im Raster
A11: fuegespalt | B11: 01-Eingaben | C11: B10 | D11: =INDIRECT("'"&B11&"'!"&C11) -> 2 | E11: mm | F11: Fuegespalt zwischen Trays
